Watching for file changes with StatReloader
Performing system checks...

System check identified no issues (0 silenced).
April 16, 2022 - 22:38:18
Django version 4.0.4, using settings 'restserver.settings'
Starting development server at http://0.0.0.0:7000/
Quit the server with CONTROL-C.
Watching for file changes with StatReloader
/Users/amolc/2020/restapi/restserver/restserver/settings.py changed, reloading.
Performing system checks...

System check identified no issues (0 silenced).
April 16, 2022 - 22:38:58
Django version 4.0.4, using settings 'restserver.settings'
Starting development server at http://0.0.0.0:7000/
Quit the server with CONTROL-C.
Watching for file changes with StatReloader
Exception in thread django-main-thread:
Traceback (most recent call last):
  File "/Users/amolc/opt/anaconda3/lib/python3.8/threading.py", line 932, in _bootstrap_inner
    self.run()
  File "/Users/amolc/opt/anaconda3/lib/python3.8/threading.py", line 870, in run
    self._target(*self._args, **self._kwargs)
  File "/Users/amolc/2020/shops/env/lib/python3.8/site-packages/django/utils/autoreload.py", line 64, in wrapper
    fn(*args, **kwargs)
  File "/Users/amolc/2020/shops/env/lib/python3.8/site-packages/django/core/management/commands/runserver.py", line 125, in inner_run
    autoreload.raise_last_exception()
  File "/Users/amolc/2020/shops/env/lib/python3.8/site-packages/django/utils/autoreload.py", line 87, in raise_last_exception
    raise _exception[1]
  File "/Users/amolc/2020/shops/env/lib/python3.8/site-packages/django/core/management/__init__.py", line 398, in execute
    autoreload.check_errors(django.setup)()
  File "/Users/amolc/2020/shops/env/lib/python3.8/site-packages/django/utils/autoreload.py", line 64, in wrapper
    fn(*args, **kwargs)
  File "/Users/amolc/2020/shops/env/lib/python3.8/site-packages/django/__init__.py", line 24, in setup
    apps.populate(settings.INSTALLED_APPS)
  File "/Users/amolc/2020/shops/env/lib/python3.8/site-packages/django/apps/registry.py", line 124, in populate
    app_config.ready()
  File "/Users/amolc/2020/shops/env/lib/python3.8/site-packages/django/contrib/admin/apps.py", line 27, in ready
    self.module.autodiscover()
  File "/Users/amolc/2020/shops/env/lib/python3.8/site-packages/django/contrib/admin/__init__.py", line 50, in autodiscover
    autodiscover_modules("admin", register_to=site)
  File "/Users/amolc/2020/shops/env/lib/python3.8/site-packages/django/utils/module_loading.py", line 58, in autodiscover_modules
    import_module("%s.%s" % (app_config.name, module_to_search))
  File "/Users/amolc/opt/anaconda3/lib/python3.8/importlib/__init__.py", line 127, in import_module
    return _bootstrap._gcd_import(name[level:], package, level)
  File "<frozen importlib._bootstrap>", line 1014, in _gcd_import
  File "<frozen importlib._bootstrap>", line 991, in _find_and_load
  File "<frozen importlib._bootstrap>", line 975, in _find_and_load_unlocked
  File "<frozen importlib._bootstrap>", line 671, in _load_unlocked
  File "<frozen importlib._bootstrap_external>", line 783, in exec_module
  File "<frozen importlib._bootstrap>", line 219, in _call_with_frames_removed
  File "/Users/amolc/2020/restapi/restserver/org/admin.py", line 4, in <module>
    from .models import Organization
ImportError: cannot import name 'Organization' from 'org.models' (/Users/amolc/2020/restapi/restserver/org/models.py)
/Users/amolc/2020/restapi/restserver/org/models.py changed, reloading.
Watching for file changes with StatReloader
Exception in thread django-main-thread:
Traceback (most recent call last):
  File "/Users/amolc/opt/anaconda3/lib/python3.8/threading.py", line 932, in _bootstrap_inner
    self.run()
  File "/Users/amolc/opt/anaconda3/lib/python3.8/threading.py", line 870, in run
    self._target(*self._args, **self._kwargs)
  File "/Users/amolc/2020/shops/env/lib/python3.8/site-packages/django/utils/autoreload.py", line 64, in wrapper
    fn(*args, **kwargs)
  File "/Users/amolc/2020/shops/env/lib/python3.8/site-packages/django/core/management/commands/runserver.py", line 125, in inner_run
    autoreload.raise_last_exception()
  File "/Users/amolc/2020/shops/env/lib/python3.8/site-packages/django/utils/autoreload.py", line 87, in raise_last_exception
    raise _exception[1]
  File "/Users/amolc/2020/shops/env/lib/python3.8/site-packages/django/core/management/__init__.py", line 398, in execute
    autoreload.check_errors(django.setup)()
  File "/Users/amolc/2020/shops/env/lib/python3.8/site-packages/django/utils/autoreload.py", line 64, in wrapper
    fn(*args, **kwargs)
  File "/Users/amolc/2020/shops/env/lib/python3.8/site-packages/django/__init__.py", line 24, in setup
    apps.populate(settings.INSTALLED_APPS)
  File "/Users/amolc/2020/shops/env/lib/python3.8/site-packages/django/apps/registry.py", line 124, in populate
    app_config.ready()
  File "/Users/amolc/2020/shops/env/lib/python3.8/site-packages/django/contrib/admin/apps.py", line 27, in ready
    self.module.autodiscover()
  File "/Users/amolc/2020/shops/env/lib/python3.8/site-packages/django/contrib/admin/__init__.py", line 50, in autodiscover
    autodiscover_modules("admin", register_to=site)
  File "/Users/amolc/2020/shops/env/lib/python3.8/site-packages/django/utils/module_loading.py", line 58, in autodiscover_modules
    import_module("%s.%s" % (app_config.name, module_to_search))
  File "/Users/amolc/opt/anaconda3/lib/python3.8/importlib/__init__.py", line 127, in import_module
    return _bootstrap._gcd_import(name[level:], package, level)
  File "<frozen importlib._bootstrap>", line 1014, in _gcd_import
  File "<frozen importlib._bootstrap>", line 991, in _find_and_load
  File "<frozen importlib._bootstrap>", line 975, in _find_and_load_unlocked
  File "<frozen importlib._bootstrap>", line 671, in _load_unlocked
  File "<frozen importlib._bootstrap_external>", line 783, in exec_module
  File "<frozen importlib._bootstrap>", line 219, in _call_with_frames_removed
  File "/Users/amolc/2020/restapi/restserver/org/admin.py", line 4, in <module>
    from .models import Organization
ImportError: cannot import name 'Organization' from 'org.models' (/Users/amolc/2020/restapi/restserver/org/models.py)
/Users/amolc/2020/restapi/restserver/org/admin.py changed, reloading.
Watching for file changes with StatReloader
Exception in thread django-main-thread:
Traceback (most recent call last):
  File "/Users/amolc/opt/anaconda3/lib/python3.8/threading.py", line 932, in _bootstrap_inner
    self.run()
  File "/Users/amolc/opt/anaconda3/lib/python3.8/threading.py", line 870, in run
    self._target(*self._args, **self._kwargs)
  File "/Users/amolc/2020/shops/env/lib/python3.8/site-packages/django/utils/autoreload.py", line 64, in wrapper
    fn(*args, **kwargs)
  File "/Users/amolc/2020/shops/env/lib/python3.8/site-packages/django/core/management/commands/runserver.py", line 125, in inner_run
    autoreload.raise_last_exception()
  File "/Users/amolc/2020/shops/env/lib/python3.8/site-packages/django/utils/autoreload.py", line 87, in raise_last_exception
    raise _exception[1]
  File "/Users/amolc/2020/shops/env/lib/python3.8/site-packages/django/core/management/__init__.py", line 398, in execute
    autoreload.check_errors(django.setup)()
  File "/Users/amolc/2020/shops/env/lib/python3.8/site-packages/django/utils/autoreload.py", line 64, in wrapper
    fn(*args, **kwargs)
  File "/Users/amolc/2020/shops/env/lib/python3.8/site-packages/django/__init__.py", line 24, in setup
    apps.populate(settings.INSTALLED_APPS)
  File "/Users/amolc/2020/shops/env/lib/python3.8/site-packages/django/apps/registry.py", line 124, in populate
    app_config.ready()
  File "/Users/amolc/2020/shops/env/lib/python3.8/site-packages/django/contrib/admin/apps.py", line 27, in ready
    self.module.autodiscover()
  File "/Users/amolc/2020/shops/env/lib/python3.8/site-packages/django/contrib/admin/__init__.py", line 50, in autodiscover
    autodiscover_modules("admin", register_to=site)
  File "/Users/amolc/2020/shops/env/lib/python3.8/site-packages/django/utils/module_loading.py", line 58, in autodiscover_modules
    import_module("%s.%s" % (app_config.name, module_to_search))
  File "/Users/amolc/opt/anaconda3/lib/python3.8/importlib/__init__.py", line 127, in import_module
    return _bootstrap._gcd_import(name[level:], package, level)
  File "<frozen importlib._bootstrap>", line 1014, in _gcd_import
  File "<frozen importlib._bootstrap>", line 991, in _find_and_load
  File "<frozen importlib._bootstrap>", line 975, in _find_and_load_unlocked
  File "<frozen importlib._bootstrap>", line 671, in _load_unlocked
  File "<frozen importlib._bootstrap_external>", line 783, in exec_module
  File "<frozen importlib._bootstrap>", line 219, in _call_with_frames_removed
  File "/Users/amolc/2020/restapi/restserver/org/admin.py", line 3, in <module>
    from .models import Org
ImportError: cannot import name 'Org' from 'org.models' (/Users/amolc/2020/restapi/restserver/org/models.py)
/Users/amolc/2020/restapi/restserver/org/admin.py changed, reloading.
Watching for file changes with StatReloader
Exception in thread django-main-thread:
Traceback (most recent call last):
  File "/Users/amolc/opt/anaconda3/lib/python3.8/threading.py", line 932, in _bootstrap_inner
    self.run()
  File "/Users/amolc/opt/anaconda3/lib/python3.8/threading.py", line 870, in run
    self._target(*self._args, **self._kwargs)
  File "/Users/amolc/2020/shops/env/lib/python3.8/site-packages/django/utils/autoreload.py", line 64, in wrapper
    fn(*args, **kwargs)
  File "/Users/amolc/2020/shops/env/lib/python3.8/site-packages/django/core/management/commands/runserver.py", line 125, in inner_run
    autoreload.raise_last_exception()
  File "/Users/amolc/2020/shops/env/lib/python3.8/site-packages/django/utils/autoreload.py", line 87, in raise_last_exception
    raise _exception[1]
  File "/Users/amolc/2020/shops/env/lib/python3.8/site-packages/django/core/management/__init__.py", line 398, in execute
    autoreload.check_errors(django.setup)()
  File "/Users/amolc/2020/shops/env/lib/python3.8/site-packages/django/utils/autoreload.py", line 64, in wrapper
    fn(*args, **kwargs)
  File "/Users/amolc/2020/shops/env/lib/python3.8/site-packages/django/__init__.py", line 24, in setup
    apps.populate(settings.INSTALLED_APPS)
  File "/Users/amolc/2020/shops/env/lib/python3.8/site-packages/django/apps/registry.py", line 124, in populate
    app_config.ready()
  File "/Users/amolc/2020/shops/env/lib/python3.8/site-packages/django/contrib/admin/apps.py", line 27, in ready
    self.module.autodiscover()
  File "/Users/amolc/2020/shops/env/lib/python3.8/site-packages/django/contrib/admin/__init__.py", line 50, in autodiscover
    autodiscover_modules("admin", register_to=site)
  File "/Users/amolc/2020/shops/env/lib/python3.8/site-packages/django/utils/module_loading.py", line 58, in autodiscover_modules
    import_module("%s.%s" % (app_config.name, module_to_search))
  File "/Users/amolc/opt/anaconda3/lib/python3.8/importlib/__init__.py", line 127, in import_module
    return _bootstrap._gcd_import(name[level:], package, level)
  File "<frozen importlib._bootstrap>", line 1014, in _gcd_import
  File "<frozen importlib._bootstrap>", line 991, in _find_and_load
  File "<frozen importlib._bootstrap>", line 975, in _find_and_load_unlocked
  File "<frozen importlib._bootstrap>", line 671, in _load_unlocked
  File "<frozen importlib._bootstrap_external>", line 783, in exec_module
  File "<frozen importlib._bootstrap>", line 219, in _call_with_frames_removed
  File "/Users/amolc/2020/restapi/restserver/org/admin.py", line 5, in <module>
    admin.site.register(Org)
NameError: name 'Org' is not defined
/Users/amolc/2020/restapi/restserver/org/admin.py changed, reloading.
Watching for file changes with StatReloader
Exception in thread django-main-thread:
Traceback (most recent call last):
  File "/Users/amolc/opt/anaconda3/lib/python3.8/threading.py", line 932, in _bootstrap_inner
    self.run()
  File "/Users/amolc/opt/anaconda3/lib/python3.8/threading.py", line 870, in run
    self._target(*self._args, **self._kwargs)
  File "/Users/amolc/2020/shops/env/lib/python3.8/site-packages/django/utils/autoreload.py", line 64, in wrapper
    fn(*args, **kwargs)
  File "/Users/amolc/2020/shops/env/lib/python3.8/site-packages/django/core/management/commands/runserver.py", line 125, in inner_run
    autoreload.raise_last_exception()
  File "/Users/amolc/2020/shops/env/lib/python3.8/site-packages/django/utils/autoreload.py", line 87, in raise_last_exception
    raise _exception[1]
  File "/Users/amolc/2020/shops/env/lib/python3.8/site-packages/django/core/management/__init__.py", line 398, in execute
    autoreload.check_errors(django.setup)()
  File "/Users/amolc/2020/shops/env/lib/python3.8/site-packages/django/utils/autoreload.py", line 64, in wrapper
    fn(*args, **kwargs)
  File "/Users/amolc/2020/shops/env/lib/python3.8/site-packages/django/__init__.py", line 24, in setup
    apps.populate(settings.INSTALLED_APPS)
  File "/Users/amolc/2020/shops/env/lib/python3.8/site-packages/django/apps/registry.py", line 124, in populate
    app_config.ready()
  File "/Users/amolc/2020/shops/env/lib/python3.8/site-packages/django/contrib/admin/apps.py", line 27, in ready
    self.module.autodiscover()
  File "/Users/amolc/2020/shops/env/lib/python3.8/site-packages/django/contrib/admin/__init__.py", line 50, in autodiscover
    autodiscover_modules("admin", register_to=site)
  File "/Users/amolc/2020/shops/env/lib/python3.8/site-packages/django/utils/module_loading.py", line 58, in autodiscover_modules
    import_module("%s.%s" % (app_config.name, module_to_search))
  File "/Users/amolc/opt/anaconda3/lib/python3.8/importlib/__init__.py", line 127, in import_module
    return _bootstrap._gcd_import(name[level:], package, level)
  File "<frozen importlib._bootstrap>", line 1014, in _gcd_import
  File "<frozen importlib._bootstrap>", line 991, in _find_and_load
  File "<frozen importlib._bootstrap>", line 975, in _find_and_load_unlocked
  File "<frozen importlib._bootstrap>", line 671, in _load_unlocked
  File "<frozen importlib._bootstrap_external>", line 783, in exec_module
  File "<frozen importlib._bootstrap>", line 219, in _call_with_frames_removed
  File "/Users/amolc/2020/restapi/restserver/users/admin.py", line 3, in <module>
    from .models import Users
ImportError: cannot import name 'Users' from 'users.models' (/Users/amolc/2020/restapi/restserver/users/models.py)
/Users/amolc/2020/restapi/restserver/org/models.py changed, reloading.
Watching for file changes with StatReloader
Exception in thread django-main-thread:
Traceback (most recent call last):
  File "/Users/amolc/opt/anaconda3/lib/python3.8/threading.py", line 932, in _bootstrap_inner
    self.run()
  File "/Users/amolc/opt/anaconda3/lib/python3.8/threading.py", line 870, in run
    self._target(*self._args, **self._kwargs)
  File "/Users/amolc/2020/shops/env/lib/python3.8/site-packages/django/utils/autoreload.py", line 64, in wrapper
    fn(*args, **kwargs)
  File "/Users/amolc/2020/shops/env/lib/python3.8/site-packages/django/core/management/commands/runserver.py", line 125, in inner_run
    autoreload.raise_last_exception()
  File "/Users/amolc/2020/shops/env/lib/python3.8/site-packages/django/utils/autoreload.py", line 87, in raise_last_exception
    raise _exception[1]
  File "/Users/amolc/2020/shops/env/lib/python3.8/site-packages/django/core/management/__init__.py", line 398, in execute
    autoreload.check_errors(django.setup)()
  File "/Users/amolc/2020/shops/env/lib/python3.8/site-packages/django/utils/autoreload.py", line 64, in wrapper
    fn(*args, **kwargs)
  File "/Users/amolc/2020/shops/env/lib/python3.8/site-packages/django/__init__.py", line 24, in setup
    apps.populate(settings.INSTALLED_APPS)
  File "/Users/amolc/2020/shops/env/lib/python3.8/site-packages/django/apps/registry.py", line 124, in populate
    app_config.ready()
  File "/Users/amolc/2020/shops/env/lib/python3.8/site-packages/django/contrib/admin/apps.py", line 27, in ready
    self.module.autodiscover()
  File "/Users/amolc/2020/shops/env/lib/python3.8/site-packages/django/contrib/admin/__init__.py", line 50, in autodiscover
    autodiscover_modules("admin", register_to=site)
  File "/Users/amolc/2020/shops/env/lib/python3.8/site-packages/django/utils/module_loading.py", line 58, in autodiscover_modules
    import_module("%s.%s" % (app_config.name, module_to_search))
  File "/Users/amolc/opt/anaconda3/lib/python3.8/importlib/__init__.py", line 127, in import_module
    return _bootstrap._gcd_import(name[level:], package, level)
  File "<frozen importlib._bootstrap>", line 1014, in _gcd_import
  File "<frozen importlib._bootstrap>", line 991, in _find_and_load
  File "<frozen importlib._bootstrap>", line 975, in _find_and_load_unlocked
  File "<frozen importlib._bootstrap>", line 671, in _load_unlocked
  File "<frozen importlib._bootstrap_external>", line 783, in exec_module
  File "<frozen importlib._bootstrap>", line 219, in _call_with_frames_removed
  File "/Users/amolc/2020/restapi/restserver/org/admin.py", line 3, in <module>
    from .models import org
ImportError: cannot import name 'org' from 'org.models' (/Users/amolc/2020/restapi/restserver/org/models.py)
/Users/amolc/2020/restapi/restserver/org/admin.py changed, reloading.
Watching for file changes with StatReloader
Exception in thread django-main-thread:
Traceback (most recent call last):
  File "/Users/amolc/opt/anaconda3/lib/python3.8/threading.py", line 932, in _bootstrap_inner
    self.run()
  File "/Users/amolc/opt/anaconda3/lib/python3.8/threading.py", line 870, in run
    self._target(*self._args, **self._kwargs)
  File "/Users/amolc/2020/shops/env/lib/python3.8/site-packages/django/utils/autoreload.py", line 64, in wrapper
    fn(*args, **kwargs)
  File "/Users/amolc/2020/shops/env/lib/python3.8/site-packages/django/core/management/commands/runserver.py", line 125, in inner_run
    autoreload.raise_last_exception()
  File "/Users/amolc/2020/shops/env/lib/python3.8/site-packages/django/utils/autoreload.py", line 87, in raise_last_exception
    raise _exception[1]
  File "/Users/amolc/2020/shops/env/lib/python3.8/site-packages/django/core/management/__init__.py", line 398, in execute
    autoreload.check_errors(django.setup)()
  File "/Users/amolc/2020/shops/env/lib/python3.8/site-packages/django/utils/autoreload.py", line 64, in wrapper
    fn(*args, **kwargs)
  File "/Users/amolc/2020/shops/env/lib/python3.8/site-packages/django/__init__.py", line 24, in setup
    apps.populate(settings.INSTALLED_APPS)
  File "/Users/amolc/2020/shops/env/lib/python3.8/site-packages/django/apps/registry.py", line 124, in populate
    app_config.ready()
  File "/Users/amolc/2020/shops/env/lib/python3.8/site-packages/django/contrib/admin/apps.py", line 27, in ready
    self.module.autodiscover()
  File "/Users/amolc/2020/shops/env/lib/python3.8/site-packages/django/contrib/admin/__init__.py", line 50, in autodiscover
    autodiscover_modules("admin", register_to=site)
  File "/Users/amolc/2020/shops/env/lib/python3.8/site-packages/django/utils/module_loading.py", line 58, in autodiscover_modules
    import_module("%s.%s" % (app_config.name, module_to_search))
  File "/Users/amolc/opt/anaconda3/lib/python3.8/importlib/__init__.py", line 127, in import_module
    return _bootstrap._gcd_import(name[level:], package, level)
  File "<frozen importlib._bootstrap>", line 1014, in _gcd_import
  File "<frozen importlib._bootstrap>", line 991, in _find_and_load
  File "<frozen importlib._bootstrap>", line 975, in _find_and_load_unlocked
  File "<frozen importlib._bootstrap>", line 671, in _load_unlocked
  File "<frozen importlib._bootstrap_external>", line 783, in exec_module
  File "<frozen importlib._bootstrap>", line 219, in _call_with_frames_removed
  File "/Users/amolc/2020/restapi/restserver/users/admin.py", line 3, in <module>
    from .models import Users
ImportError: cannot import name 'Users' from 'users.models' (/Users/amolc/2020/restapi/restserver/users/models.py)
/Users/amolc/2020/restapi/restserver/org/admin.py changed, reloading.
Watching for file changes with StatReloader
Exception in thread django-main-thread:
Traceback (most recent call last):
  File "/Users/amolc/opt/anaconda3/lib/python3.8/threading.py", line 932, in _bootstrap_inner
    self.run()
  File "/Users/amolc/opt/anaconda3/lib/python3.8/threading.py", line 870, in run
    self._target(*self._args, **self._kwargs)
  File "/Users/amolc/2020/shops/env/lib/python3.8/site-packages/django/utils/autoreload.py", line 64, in wrapper
    fn(*args, **kwargs)
  File "/Users/amolc/2020/shops/env/lib/python3.8/site-packages/django/core/management/commands/runserver.py", line 125, in inner_run
    autoreload.raise_last_exception()
  File "/Users/amolc/2020/shops/env/lib/python3.8/site-packages/django/utils/autoreload.py", line 87, in raise_last_exception
    raise _exception[1]
  File "/Users/amolc/2020/shops/env/lib/python3.8/site-packages/django/core/management/__init__.py", line 398, in execute
    autoreload.check_errors(django.setup)()
  File "/Users/amolc/2020/shops/env/lib/python3.8/site-packages/django/utils/autoreload.py", line 64, in wrapper
    fn(*args, **kwargs)
  File "/Users/amolc/2020/shops/env/lib/python3.8/site-packages/django/__init__.py", line 24, in setup
    apps.populate(settings.INSTALLED_APPS)
  File "/Users/amolc/2020/shops/env/lib/python3.8/site-packages/django/apps/registry.py", line 124, in populate
    app_config.ready()
  File "/Users/amolc/2020/shops/env/lib/python3.8/site-packages/django/contrib/admin/apps.py", line 27, in ready
    self.module.autodiscover()
  File "/Users/amolc/2020/shops/env/lib/python3.8/site-packages/django/contrib/admin/__init__.py", line 50, in autodiscover
    autodiscover_modules("admin", register_to=site)
  File "/Users/amolc/2020/shops/env/lib/python3.8/site-packages/django/utils/module_loading.py", line 58, in autodiscover_modules
    import_module("%s.%s" % (app_config.name, module_to_search))
  File "/Users/amolc/opt/anaconda3/lib/python3.8/importlib/__init__.py", line 127, in import_module
    return _bootstrap._gcd_import(name[level:], package, level)
  File "<frozen importlib._bootstrap>", line 1014, in _gcd_import
  File "<frozen importlib._bootstrap>", line 991, in _find_and_load
  File "<frozen importlib._bootstrap>", line 975, in _find_and_load_unlocked
  File "<frozen importlib._bootstrap>", line 671, in _load_unlocked
  File "<frozen importlib._bootstrap_external>", line 783, in exec_module
  File "<frozen importlib._bootstrap>", line 219, in _call_with_frames_removed
  File "/Users/amolc/2020/restapi/restserver/users/admin.py", line 3, in <module>
    from .models import Users
ImportError: cannot import name 'Users' from 'users.models' (/Users/amolc/2020/restapi/restserver/users/models.py)
/Users/amolc/2020/restapi/restserver/restserver/settings.py changed, reloading.
Watching for file changes with StatReloader
/Users/amolc/2020/restapi/restserver/restserver/urls.py changed, reloading.
Performing system checks...

System check identified no issues (0 silenced).
April 16, 2022 - 23:44:08
Django version 4.0.4, using settings 'restserver.settings'
Starting development server at http://0.0.0.0:7000/
Quit the server with CONTROL-C.
Watching for file changes with StatReloader
/Users/amolc/2020/restapi/restserver/restserver/urls.py changed, reloading.
Performing system checks...

System check identified no issues (0 silenced).
April 16, 2022 - 23:52:25
Django version 4.0.4, using settings 'restserver.settings'
Starting development server at http://0.0.0.0:7000/
Quit the server with CONTROL-C.
Watching for file changes with StatReloader
Exception in thread django-main-thread:
Traceback (most recent call last):
  File "/Users/amolc/opt/anaconda3/lib/python3.8/threading.py", line 932, in _bootstrap_inner
    self.run()
  File "/Users/amolc/opt/anaconda3/lib/python3.8/threading.py", line 870, in run
    self._target(*self._args, **self._kwargs)
  File "/Users/amolc/2020/shops/env/lib/python3.8/site-packages/django/utils/autoreload.py", line 64, in wrapper
    fn(*args, **kwargs)
  File "/Users/amolc/2020/shops/env/lib/python3.8/site-packages/django/core/management/commands/runserver.py", line 134, in inner_run
    self.check(display_num_errors=True)
  File "/Users/amolc/2020/shops/env/lib/python3.8/site-packages/django/core/management/base.py", line 487, in check
    all_issues = checks.run_checks(
  File "/Users/amolc/2020/shops/env/lib/python3.8/site-packages/django/core/checks/registry.py", line 88, in run_checks
    new_errors = check(app_configs=app_configs, databases=databases)
  File "/Users/amolc/2020/shops/env/lib/python3.8/site-packages/django/core/checks/urls.py", line 42, in check_url_namespaces_unique
    all_namespaces = _load_all_namespaces(resolver)
  File "/Users/amolc/2020/shops/env/lib/python3.8/site-packages/django/core/checks/urls.py", line 61, in _load_all_namespaces
    url_patterns = getattr(resolver, "url_patterns", [])
  File "/Users/amolc/2020/shops/env/lib/python3.8/site-packages/django/utils/functional.py", line 49, in __get__
    res = instance.__dict__[self.name] = self.func(instance)
  File "/Users/amolc/2020/shops/env/lib/python3.8/site-packages/django/urls/resolvers.py", line 696, in url_patterns
    patterns = getattr(self.urlconf_module, "urlpatterns", self.urlconf_module)
  File "/Users/amolc/2020/shops/env/lib/python3.8/site-packages/django/utils/functional.py", line 49, in __get__
    res = instance.__dict__[self.name] = self.func(instance)
  File "/Users/amolc/2020/shops/env/lib/python3.8/site-packages/django/urls/resolvers.py", line 689, in urlconf_module
    return import_module(self.urlconf_name)
  File "/Users/amolc/opt/anaconda3/lib/python3.8/importlib/__init__.py", line 127, in import_module
    return _bootstrap._gcd_import(name[level:], package, level)
  File "<frozen importlib._bootstrap>", line 1014, in _gcd_import
  File "<frozen importlib._bootstrap>", line 991, in _find_and_load
  File "<frozen importlib._bootstrap>", line 975, in _find_and_load_unlocked
  File "<frozen importlib._bootstrap>", line 671, in _load_unlocked
  File "<frozen importlib._bootstrap_external>", line 783, in exec_module
  File "<frozen importlib._bootstrap>", line 219, in _call_with_frames_removed
  File "/Users/amolc/2020/restapi/restserver/restserver/urls.py", line 27, in <module>
    path('api/org', include('org.urls')),
  File "/Users/amolc/2020/shops/env/lib/python3.8/site-packages/django/urls/conf.py", line 38, in include
    urlconf_module = import_module(urlconf_module)
  File "/Users/amolc/opt/anaconda3/lib/python3.8/importlib/__init__.py", line 127, in import_module
    return _bootstrap._gcd_import(name[level:], package, level)
  File "<frozen importlib._bootstrap>", line 1014, in _gcd_import
  File "<frozen importlib._bootstrap>", line 991, in _find_and_load
  File "<frozen importlib._bootstrap>", line 973, in _find_and_load_unlocked
ModuleNotFoundError: No module named 'org.urls'
/Users/amolc/2020/restapi/restserver/restserver/settings.py changed, reloading.
Performing system checks...

Traceback (most recent call last):
  File "manage.py", line 22, in <module>
    main()
  File "manage.py", line 18, in main
    execute_from_command_line(sys.argv)
  File "/Users/amolc/2020/shops/env/lib/python3.8/site-packages/django/core/management/__init__.py", line 446, in execute_from_command_line
    utility.execute()
  File "/Users/amolc/2020/shops/env/lib/python3.8/site-packages/django/core/management/__init__.py", line 386, in execute
    settings.INSTALLED_APPS
  File "/Users/amolc/2020/shops/env/lib/python3.8/site-packages/django/conf/__init__.py", line 87, in __getattr__
    self._setup(name)
  File "/Users/amolc/2020/shops/env/lib/python3.8/site-packages/django/conf/__init__.py", line 74, in _setup
    self._wrapped = Settings(settings_module)
  File "/Users/amolc/2020/shops/env/lib/python3.8/site-packages/django/conf/__init__.py", line 183, in __init__
    mod = importlib.import_module(self.SETTINGS_MODULE)
  File "/Users/amolc/opt/anaconda3/lib/python3.8/importlib/__init__.py", line 127, in import_module
    return _bootstrap._gcd_import(name[level:], package, level)
  File "<frozen importlib._bootstrap>", line 1014, in _gcd_import
  File "<frozen importlib._bootstrap>", line 991, in _find_and_load
  File "<frozen importlib._bootstrap>", line 975, in _find_and_load_unlocked
  File "<frozen importlib._bootstrap>", line 671, in _load_unlocked
  File "<frozen importlib._bootstrap_external>", line 779, in exec_module
  File "<frozen importlib._bootstrap_external>", line 916, in get_code
  File "<frozen importlib._bootstrap_external>", line 846, in source_to_code
  File "<frozen importlib._bootstrap>", line 219, in _call_with_frames_removed
  File "/Users/amolc/2020/restapi/restserver/restserver/settings.py", line 43
    'org'python3 manage.py migrate
         ^
SyntaxError: invalid syntax
